Workbook

Sheet COMP
A1: DENOMINACIÓN DEL PUESTO | B1: Usuario | C1: Contraseña | D1: TIPO DE CARGA
A2: Alcaldía
A3: Secretaría Particular
A4: Subdirección de Control de Gestión
A5: Coordinación de la Unidad de Transparencia, Acceso a la Información Pública, Datos Personales y Archivos
A6: Jefatura de Unidad Departamental de Acceso a la Información Pública y Datos Personales
A7: Jefatura de Unidad Departamental de Archivos
A8: Dirección de Comunicación Social | B8: Direccioncomsocial@indicadorestlalpan.mx | C8: comunicasocial2189312 | D8: Formulario (si aplica) / Cargar Excel (si aplica) / Ver datos / Ver gráficos
A9: Líder Coordinador de Proyectos de Servicios Digitales
A10: Jefatura de Unidad Departamental de Comunicación
A11: Jefatura de Unidad Departamental de Difusión
A12: Dirección de Planeación del Desarrollo
A13: Jefatura de Unidad Departamental de Planeación y Formulación de Proyectos de la Alcaldía
A14: Jefatura de Unidad Departamental de Apoyo Técnico y Evaluación de Programas con Reglas de Operación
A15: Dirección del Centro de Servicios y Atención Ciudadana | B15: direciudadana@indicadorestlalpan.mx | C15: direcaten774
A16: Subdirección de Atención Ciudadana
A17: Enlace de Información y Seguimiento a Solicitudes de Servicios “A”
A18: Enlace de Información y Seguimiento a Solicitudes de Servicios “B”
A19: Subdirección de Ventanilla Única de Trámites | B19: subventatramites@indicadorestlalpan.mx | C19: ventanitrami498 | D19: Formulario (si aplica) / Cargar Excel (si aplica) / Ver datos / Ver gráficos
A20: Enlace de Atención Ciudadana “A”
A21: Enlace de Atención Ciudadana “B”
A22: Enlace de Atención Ciudadana “C”
A23: Enlace de Atención Ciudadana “D”
A24: Dirección de la Unidad de Gestión Integral de Riesgos y Protección Civil
A25: Jefatura de Unidad Departamental de Dictaminación de Riesgos | B25: judictaminariesgo@indicadorestlalpan.mx | C25: dictariesgooss893 | D25: Formulario (si aplica) / Cargar Excel (si aplica) / Ver datos / Ver gráficos
A26: Jefatura de Unidad Departamental de Respuesta a Emergencias | B26: judrespuestaseme@indicadorestlalpan.mx | C26: emerrespues5237 | D26: Formulario (si aplica) / Cargar Excel (si aplica) / Ver datos / Ver gráficos
A27: Subdirección de Atención a Emergencias y Gestión de Riesgos | B27: subatencionemergias@indicadorestlalpan.mx | C27: subemerg5455
A28: Líder Coordinador de Proyectos de Mitigación de Riesgos
A29: Jefatura de la Oficina de Asesores y Coordinación Territorial | B29: coordinacionterritorial@indicadorestlalpan.mx | C29: coorterri32094820 | D29: Formulario (si aplica) / Cargar Excel (si aplica) / Ver datos / Ver gráficos | E29: DE SUS ÁREAS. Ver datos / Ver gráficos
A30: Subdirección Territorial A | B30: subterritorialA@indicadorestlalpan.mx | C30: suubterrri4r4 | D30: Formulario (si aplica) / Cargar Excel (si aplica) / Ver datos / Ver gráficos
A31: Líder Coordinador de Proyectos de Administración “A"
A32: Jefatura de Unidad Departamental de Obras "A"
A33: Jefatura de Unidad Departamental de Servicios Urbanos “A"
A34: Subdirección Territorial B | B34: subterritorialB@indicadorestlalpan.mx | C34: suuubterrri564 | D34: Formulario (si aplica) / Cargar Excel (si aplica) / Ver datos / Ver gráficos
A35: Líder Coordinador de Proyectos de Administración “B"
A36: Jefatura de Unidad Departamental de Obras “B"
A37: Jefatura de Unidad Departamental de Servicios Urbanos “B"
A38: Subdirección Territorial C | B38: subterritorialC@indicadorestlalpan.mx | C38: suuub456 | D38: Formulario (si aplica) / Cargar Excel (si aplica) / Ver datos / Ver gráficos
A39: Líder Coordinador de Proyectos de Administración “C"
A40: Jefatura de Unidad Departamental de Obras “C"
...

Sheet Hoja1
B1: CONTRASEÑA | D1: Contenido de la cuenta
A2: Tlalpan@indicadorestlalpan.mx | B2: tlalp379873248@ | D2: Subir excel | E2: Graficas | F2: Ver datos excel
D3: Formulario de datos | F3: ver datos formulario
A5: DIRECCIÓN ATENCIÓN GPT | B5: CONTRASEÑA | C5: Contenido
A6: Direcciongruposprioritarios@indicadorestlalpan.mx | B6: prioritariosgrup98148 | C6: DE SU CARGA. Formulario (si aplica) / Cargar Excel (si aplica) / Ver datos / Ver gráficos | D6: DE SUS ÁREAS. Ver datos / Ver gráficos | E6: =IF(COUNTIF(COMP!$B:$B, A6)>0, "EXISTE", " ") -> EXISTE
A7: JUDAtencionpoblacionmayor@indicadorestlalpan.mx | B7: adultamayor2134 | C7: Formulario (si aplica) / Cargar Excel (si aplica) / Ver datos / Ver gráficos | E7: =IF(COUNTIF(COMP!$B:$B, A7)>0, "EXISTE", " ") -> EXISTE
A8: JUDAtencioninfancias@indicadorestlalpan.mx | B8: infanciajud789 | C8: Formulario (si aplica) / Cargar Excel (si aplica) / Ver datos / Ver gráficos | E8: =IF(COUNTIF(COMP!$B:$B, A8)>0, "EXISTE", " ") -> EXISTE
A9: JUDAtencionjuventud@indicadorestlalpan.mx | B9: juventudatencion28793 | C9: Formulario (si aplica) / Cargar Excel (si aplica) / Ver datos / Ver gráficos | E9: =IF(COUNTIF(COMP!$B:$B, A9)>0, "EXISTE", " ") -> EXISTE
A10: JUDDesarrolocomunitario@indicadorestlalpan.mx | B10: centerint124 | C10: Formulario (si aplica) / Cargar Excel (si aplica) / Ver datos / Ver gráficos | E10: =IF(COUNTIF(COMP!$B:$B, A10)>0, "EXISTE", " ") -> EXISTE
E11: =IF(COUNTIF(COMP!$B:$B, A11)>0, "EXISTE", " ")
A12: Subdirección de Ordenamiento y Movilidad | B12: Contraseña | E12: =IF(COUNTIF(COMP!$B:$B, A12)>0, "EXISTE", " ")
A13: movilidad@indicadorestlalpan.mx | B13: movisub6968 | C13: Formulario (si aplica) / Cargar Excel (si aplica) / Ver datos / Ver gráficos | E13: =IF(COUNTIF(COMP!$B:$B, A13)>0, "EXISTE", " ") -> EXISTE
E14: =IF(COUNTIF(COMP!$B:$B, A14)>0, "EXISTE", " ")
A15: Subdirección de Obras | B15: Contraseña | E15: =IF(COUNTIF(COMP!$B:$B, A15)>0, "EXISTE", " ")
A16: subdirecciondeobras@indicadorestlalpan.mx | B16: subdir2345 | C16: Ver datos / Ver gráficos | E16: =IF(COUNTIF(COMP!$B:$B, A16)>0, "EXISTE", " ") -> EXISTE
A17: JUDMantenimientoEdificios@indicadorestlalpan.mx | B17: mantedificios2323 | C17: Formulario (si aplica) / Cargar Excel (si aplica) / Ver datos / Ver gráficos | E17: =IF(COUNTIF(COMP!$B:$B, A17)>0, "EXISTE", " ") -> EXISTE
A18: JUDPlantelesEducativos@indicadorestlalpan.mx | B18: educativo2099 | C18: Formulario (si aplica) / Cargar Excel (si aplica) / Ver datos / Ver gráficos | E18: =IF(COUNTIF(COMP!$B:$B, A18)>0, "EXISTE", " ") -> EXISTE
A19: JUDConstruccionEdificios@indicadorestlalpan.mx | B19: JUDconstruccion | C19: Formulario (si aplica) / Cargar Excel (si aplica) / Ver datos / Ver gráficos | E19: =IF(COUNTIF(COMP!$B:$B, A19)>0, "EXISTE", " ") -> EXISTE
A20: JUDObrasViales@indicadorestlalpan.mx | B20: viales3435 | C20: Formulario (si aplica) / Cargar Excel (si aplica) / Ver datos / Ver gráficos | E20: =IF(COUNTIF(COMP!$B:$B, A20)>0, "EXISTE", " ") -> EXISTE
E21: =IF(COUNTIF(COMP!$B:$B, A21)>0, "EXISTE", " ")
A22: JUD de Incidencia y Estadística Delictiva | B22: Contraseña | E22: =IF(COUNTIF(COMP!$B:$B, A22)>0, "EXISTE", " ")
A23: Incidenciayestadistica@indicadorestlalpan.mx | B23: delictiva787342 | C23: Formulario (si aplica) / Cargar Excel (si aplica) / Ver datos / Ver gráficos | E23: =IF(COUNTIF(COMP!$B:$B, A23)>0, "EXISTE", " ") -> EXISTE
E24: =IF(COUNTIF(COMP!$B:$B, A24)>0, "EXISTE", " ")
A25: Centros Deportivos | B25: Contraseña | E25: =IF(COUNTIF(COMP!$B:$B, A25)>0, "EXISTE", " ")
A26: JUDcentrosdeportivos@indicadorestlalpan.mx | B26: centdepo38721 | C26: Formulario (si aplica) / Cargar Excel (si aplica) / Ver datos / Ver gráficos | E26: =IF(COUNTIF(COMP!$B:$B, A26)>0, "EXISTE", " ") -> EXISTE
E27: =IF(COUNTIF(COMP!$B:$B, A27)>0, "EXISTE", " ")
A28: Dirección de Salud | B28: Contraseña | E28: =IF(COUNTIF(COMP!$B:$B, A28)>0, "EXISTE", " ")
A29: Direccionsalud@indicadorestlalpan.mx | B29: salud64783435 | C29: DE SU CARGA. Formulario (si aplica) / Cargar Excel (si aplica) / Ver datos / Ver gráficos | D29: DE SUS ÁREAS. Ver datos / Ver gráficos | E29: =IF(COUNTIF(COMP!$B:$B, A29)>0, "EXISTE", " ") -> EXISTE
E30: =IF(COUNTIF(COMP!$B:$B, A30)>0, "EXISTE", " ")
A31: JUD Colonias y Asentamientos Humanos Irregulares | B31: Contraseña | E31: =IF(COUNTIF(COMP!$B:$B, A31)>0, "EXISTE", " ")
A32: JUDColoniasirregulares@indicadorestlalpan.mx | B32: asentamientos43928 | C32: Formulario (si aplica) / Cargar Excel (si aplica) / Ver datos / Ver gráficos | E32: =IF(COUNTIF(COMP!$B:$B, A32)>0, "EXISTE", " ") -> EXISTE
E33: =IF(COUNTIF(COMP!$B:$B, A33)>0, "EXISTE", " ")
A34: JUD de Seguridad Ciudadana y de Tránsito | B34: Contraseña | E34: =IF(COUNTIF(COMP!$B:$B, A34)>0, "EXISTE", " ")
A35: JUDSeguridadciudadanatransito@indicadorestlalpan.mx | B35: transitoo207742 | C35: Formulario (si aplica) / Cargar Excel (si aplica) / Ver datos / Ver gráficos | E35: =IF(COUNTIF(COMP!$B:$B, A35)>0, "EXISTE", " ") -> EXISTE
E36: =IF(COUNTIF(COMP!$B:$B, A36)>0, "EXISTE", " ")
A37: JUD de Control Operativo Policial | B37: Contraseña | E37: =IF(COUNTIF(COMP!$B:$B, A37)>0, "EXISTE", " ")
A38: JUDControlopetativopolicial@indicadorestlalpan.mx | B38: cop318947221 | C38: Formulario (si aplica) / Cargar Excel (si aplica) / Ver datos / Ver gráficos | E38: =IF(COUNTIF(COMP!$B:$B, A38)>0, "EXISTE", " ") -> EXISTE
E39: =IF(COUNTIF(COMP!$B:$B, A39)>0, "EXISTE", " ")
A40: JUD de Panteones | B40: Contraseña | E40: =IF(COUNTIF(COMP!$B:$B, A40)>0, "EXISTE", " ")
A41: JUDPanteones@indicadorestlalpan.mx | B41: pantlal12 | C41: Formulario (si aplica) / Cargar Excel (si aplica) / Ver datos / Ver gráficos | E41: =IF(COUNTIF(COMP!$B:$B, A41)>0, "EXISTE", " ") -> EXISTE
...
